<?xml version="1.0"?>
<robot xmlns:xacro="http://www.ros.org/wiki/xacro"  name="mobile_robot">
    <xacro:include filename="inertial_macros.xacro"/>
    <xacro:include filename="lidar.xacro"/>
    <!-- <xacro:include filename="camera.xacro"/> -->
    <xacro:include filename="gazebo_control.xacro"/>
    
    <!-- Materials -->
    <material name="white">
        <color rgba="1 1 1 1" />
    </material>

    <material name="orange">
        <color rgba="1 0.3 0.1 1"/>
    </material>

    <material name="blue">
        <color rgba="0.2 0.2 1 1"/>
    </material>

    <material name="black">
        <color rgba="0 0 0 1"/>
    </material>

    <material name="red">
        <color rgba="1 0 0 1"/>
    </material>

    <!-- Base Link -->
    <link name="base_link">
    </link>

    <!-- Chassis Link -->
    <joint name="chassis_joint" type="fixed">
        <parent link="base_link"/>
        <child link="chassis"/>
        <origin xyz="0.0 0 0.0"/>
    </joint>

    <link name="chassis">
        <visual>
            <origin xyz="0 0 0.15"/>
            <geometry>
                <box size="0.5 0.3 0.1"/>
            </geometry>
            <material name="white"/>
        </visual>
        <collision>
            <origin xyz="0 0 0.15"/>
            <geometry>
                <box size="0.5 0.3 0.1"/>
            </geometry>
        </collision>
        <xacro:inertial_box mass="1.0" x="0.5" y="0.3" z="0.1">
            <origin xyz="0 0 0" rpy="0 0 0"/>
        </xacro:inertial_box>
    </link>

    <gazebo reference="chassis">
        <material>Gazebo/White</material>
    </gazebo>

    <!-- Front Left Wheel Link -->
    <joint name="front_left_wheel_joint" type="continuous">
        <parent link="chassis"/>
        <child link="front_left_wheel"/>
        <origin xyz="0.16 0.15 0.1" rpy="-1.5708 0 0"/>
        <axis xyz="0 0 1"/>
        <limit effort="10000" velocity="1000" />
	    <dynamics damping="1.0" friction="1.0" />
    </joint>

    <link name="front_left_wheel">
        <visual>
            <geometry>
                <cylinder radius="0.08" length="0.08"/>
            </geometry>
            <material name="blue"/>
        </visual>
        <collision>
            <geometry>
                <cylinder radius="0.08" length="0.08"/>
            </geometry>
        </collision>
        <xacro:inertial_cylinder mass="1" length="0.08" radius="0.08">
            <origin xyz="0 0 0" rpy="0 0 0"/>
        </xacro:inertial_cylinder>
    </link>

    <gazebo reference="front_left_wheel">
        <material>Gazebo/Blue</material>
    </gazebo>

    <!-- Front Right Wheel Link -->
    <joint name="front_right_wheel_joint" type="continuous">
        <parent link="chassis"/>
        <child link="front_right_wheel"/>
        <origin xyz="0.16 -0.15 0.1" rpy="1.5708 0 0"/>
        <axis xyz="0 0 -1"/>
        <limit effort="10000" velocity="1000" />
	    <dynamics damping="1.0" friction="1.0" />

    </joint>

    <link name="front_right_wheel">
        <visual>
            <geometry>
                <cylinder radius="0.08" length="0.08"/>
            </geometry>
            <material name="blue"/>
        </visual>
        <collision>
            <geometry>
                <cylinder radius="0.08" length="0.08"/>
            </geometry>
        </collision>
        <xacro:inertial_cylinder mass="1" length="0.08" radius="0.08">
            <origin xyz="0 0 0" rpy="0 0 0"/>
        </xacro:inertial_cylinder>
    </link>

    <gazebo reference="front_right_wheel">
        <material>Gazebo/Blue</material>
    </gazebo>

    <!-- Rear Left Wheel Link -->
    <joint name="rear_left_wheel_joint" type="continuous">
        <parent link="chassis"/>
        <child link="rear_left_wheel"/>
        <origin xyz="-0.16 0.15 0.1" rpy="-1.5708 0 0"/>
        <axis xyz="0 0 1"/>
        <limit effort="10000" velocity="1000" />
	    <dynamics damping="1.0" friction="1.0" />
    </joint>

    <link name="rear_left_wheel">
        <visual>
            <geometry>
                <cylinder radius="0.08" length="0.08"/>
            </geometry>
            <material name="blue"/>
        </visual>
        <collision>
            <geometry>
                <cylinder radius="0.08" length="0.08"/>
            </geometry>
        </collision>
        <xacro:inertial_cylinder mass="1" length="0.08" radius="0.08">
            <origin xyz="0 0 0" rpy="0 0 0"/>
        </xacro:inertial_cylinder>
    </link>

    <gazebo reference="rear_left_wheel">
        <material>Gazebo/Blue</material>
    </gazebo>

    <!-- Rear Right Wheel Link -->
    <joint name="rear_right_wheel_joint" type="continuous">
        <parent link="chassis"/>
        <child link="rear_right_wheel"/>
        <origin xyz="-0.16 -0.15 0.1" rpy="1.5708 0 0"/>
		<axis xyz="0 0 -1"/>
        <limit effort="10000" velocity="1000" />
	    <dynamics damping="1.0" friction="1.0" />
    </joint>

    <link name="rear_right_wheel">
        <visual>
            <geometry>
                <cylinder radius="0.08" length="0.08"/>
            </geometry>
            <material name="blue"/>
        </visual>
        <collision>
            <geometry>
                <cylinder radius="0.08" length="0.08"/>
            </geometry>
        </collision>
        <xacro:inertial_cylinder mass="1" length="0.08" radius="0.08">
            <origin xyz="0 0 0" rpy="0 0 0"/>
        </xacro:inertial_cylinder>
    </link>

    <gazebo reference="rear_right_wheel">
        <material>Gazebo/Blue</material>
    </gazebo>

</robot>